File: TestFile/210 10%-1.txt
#Acq. time (s)=	1
#Accumulations=	1
#Range (nm)=	580...760
#Windows=	4
#Auto scanning=	Off
#Autofocus=	Off
#AutoExposure=	Off
#Spike filter=	Off
#Delay time (s)=	0
#Binning=	1
#Readout mode=	Signal
#DeNoise=	Off
#ICS correction=	Off
#Dark correction=	Off
#Inst. Process=	Off
#Detector temperature (°C)=	-60.16
#Instrument=	LabRAM HR Evol
#Detector=	Syncerity OE
#Objective=	x100_VIS
#Grating=	600 (500nm)
#ND Filter=	25%
#Laser=	532nm_Edge
#Hole=	300.003
#Range=	Visible
#AFM=	Off
#Laser. Pol.=	HWPL-VIS
#Raman. Pol.=	P-350/2300
#Laser Pol. (°)=	180
#Raman Pol. (°)=	130
#StageXY (mm)=	75x50
#StageZ=	Z motor
#X (µm)=	-26697.8
#Y (µm)=	-2387.3
#Z (µm)=	-1341.5
#Full time(s)=	30
#Project=	A
#Sample=	B
#Site=	C
#Title=	-30-3-0p1_77
#Remark=
#Date=	14.08.2020 14:47
#Acquired=	14.08.2020 14:47:27
580.073	22
580.23	26
580.387	30
580.544	22
580.701	22
580.858	22
581.015	20
581.172	20
581.329	20
581.486	28
581.643	24
581.8	30
581.957	18
582.114	20
582.271	24
582.429	26
582.586	26
582.743	20
582.9	30
583.057	26
583.214	22
583.371	26
583.528	28
583.685	22
583.842	20
583.999	22
584.156	24
584.313	28
584.47	20
584.627	24
584.784	24
584.941	18
585.097	26
585.254	24
585.411	24
585.568	22
585.725	20
585.882	22
586.039	14
586.196	16
586.353	24
586.51	26
586.667	22
586.824	28
586.981	24
587.138	26
587.295	22
587.452	26
587.608	16
587.765	20
587.922	22
588.079	20
588.236	26
588.393	26
588.55	22
588.707	22
588.864	24
589.02	20
589.177	20
589.334	34
589.491	26
589.648	24
589.805	28
589.962	22
590.118	22
590.275	26
590.432	20
590.589	18
590.746	22
590.903	24
591.059	16
591.216	26
591.373	24
591.53	18
591.687	22
591.843	16
592	22
592.157	26
592.314	30
592.471	20
592.627	26
592.784	28
592.941	20
593.098	38
593.255	24
593.411	16
593.568	22
593.725	26
593.882	26
594.038	18
594.195	26
594.352	24
594.508	24
594.665	16
594.822	24
594.979	30
595.135	30
595.292	26
595.449	26
595.605	26
595.762	26
595.919	26
596.076	24
596.232	24
596.389	20
596.546	26
596.702	26
596.859	24
597.016	26
597.172	28
597.329	26
597.486	24
597.642	26
597.799	20
597.956	30
598.112	24
598.269	30
598.425	24
598.582	30
598.739	20
598.895	28
599.052	22
599.208	14
599.365	32
599.522	28
599.678	32
599.835	28
599.991	24
600.148	28
600.305	30
600.461	20
600.618	32
600.774	18
600.931	26
601.087	26
601.244	26
601.401	24
601.557	28
601.714	26
601.87	30
602.027	18
602.183	26
602.34	24
602.496	28
602.653	28
602.809	30
602.966	30
603.122	24
603.279	28
603.435	26
603.592	32
603.748	24
603.905	24
604.061	24
604.218	28
604.374	22
604.531	26
604.687	30
604.843	22
605	26
605.156	30
605.313	34
605.469	30
605.626	20
605.782	22
605.938	24
606.095	30
606.251	22
606.408	28
606.564	26
606.72	30
606.877	34
607.033	20
607.19	32
607.346	26
607.502	32
607.659	26
607.815	20
607.971	36
608.128	28
608.284	26
608.441	26
608.597	28
608.753	26
608.91	26
609.066	34
609.222	32
609.379	32
609.535	30
609.691	28
609.847	16
610.004	22
610.16	28
610.316	32
610.473	28
610.629	28
610.785	12
610.942	42
611.098	22
611.254	26
611.41	14
611.567	32
611.723	34
611.879	30
612.035	34
612.192	22
612.348	28
612.504	42
612.66	20
612.816	32
612.973	24
613.129	28
613.285	34
613.441	24
613.597	26
613.754	24
613.91	28
614.066	22
614.222	26
614.378	34
614.535	32
614.691	20
614.847	22
615.003	22
615.159	28
615.315	28
615.471	38
615.628	32
615.784	24
615.94	42
616.096	26
616.252	32
616.408	24
616.564	24
616.72	36
616.877	30
617.033	28
617.189	30
617.345	24
617.501	30
617.657	30
617.813	38
617.969	28
618.125	32
618.281	24
618.437	28
618.593	24
618.749	42
618.905	36
619.061	30
619.217	30
619.373	50
619.529	34
619.685	32
619.841	32
619.997	36
620.154	32
620.31	42
620.465	24
620.621	28
620.777	34
620.933	26
621.089	40
621.245	32
621.401	42
621.557	30
621.713	40
621.869	44
622.025	40
622.181	32
622.337	34
622.493	42
622.649	36
622.805	40
622.961	27.9978
623.117	39.8806
623.272	32.0981
623.428	37.7078
623.584	28.4822
623.74	38.0978
623.896	37.8785
624.052	35.5567
624.208	33.9409
624.364	33.2267
624.519	40.5987
624.675	38.4961
624.831	41.2611
624.987	33.6437
625.143	38.131
625.299	37.2512
625.455	37.0246
625.61	26.8584
625.766	36.7139
625.922	32.4731
626.078	39.6921
626.234	39.1742
626.389	42.8079
626.545	31.7975
626.701	35.069
626.857	35.6436
627.013	41.2167
627.168	35.1221
627.324	38.4449
627.48	37.2415
627.636	36.2505
627.791	38
627.947	44.197
628.103	30.6829
628.259	39.9069
628.414	38.072
628.57	43.3787
628.726	37.2225
628.882	42.0534
629.037	37.9235
629.193	34.1081
629.349	36.3202
629.504	35.955
629.66	40.63
629.816	40.0077
629.971	36
630.127	35.9714
630.283	41.8354
630.438	37.9387
630.594	31.862
630.75	42.7271
630.905	34.8094
631.061	42
631.217	40.7438
631.372	31.8886
631.528	39.9573
631.684	44.33
631.839	34.8736
631.995	42.7555
632.15	41.8174
632.306	36.469
632.462	39.7869
632.617	34.1527
632.773	46.9925
632.928	41.7192
633.084	39.6811
633.24	43.4011
633.395	34.5616
633.549	36
633.706	34
633.862	48
634.018	34
634.174	52
634.33	34
634.487	46
634.643	48
634.799	54
634.955	42
635.111	50
635.268	42
635.424	44
635.58	44
635.736	38
635.892	48
636.049	42
636.205	42
636.361	56
636.517	42
636.673	38
636.829	38
636.985	44
637.142	40
637.298	42
637.454	46
637.61	48
637.766	42
637.922	38
638.078	44
638.234	36
638.391	46
638.547	52
638.703	42
638.859	50
639.015	40
639.171	50
639.327	44
639.483	42
639.639	48
639.795	50
639.951	50
640.107	46
640.263	44
640.419	54
640.576	44
640.732	56
640.888	54
641.044	40
641.2	50
641.356	34
641.512	46
641.668	40
641.824	48
641.98	50
642.136	44
642.292	58
642.448	38
642.604	46
642.76	38
642.916	48
643.072	52
643.228	46
643.384	34
643.54	42
643.695	56
643.851	52
644.007	46
644.163	42
644.319	40
644.475	42
644.631	54
644.787	44
644.943	36
645.099	44
645.255	36
645.411	46
645.567	44
645.722	34
645.878	42
646.034	52
646.19	46
646.346	48
646.502	42
646.658	48
646.814	42
646.969	40
647.125	38
647.281	46
647.437	48
647.593	54
647.749	46
647.905	48
648.06	46
648.216	48
648.372	48
648.528	44
648.684	50
648.839	38
648.995	48
649.151	46
649.307	40
649.463	40
649.618	52
649.774	40
649.93	50
650.086	48
650.241	40
650.397	42
650.553	50
650.709	54
650.865	44
651.02	48
651.176	50
651.332	42
651.487	48
651.643	50
651.799	48
651.955	52
652.11	58
652.266	46
652.422	48
652.577	52
652.733	60
652.889	40
653.044	42
653.2	42
653.356	46
653.511	36
653.667	58
653.823	40
653.978	50
654.134	42
654.29	50
654.445	54
654.601	52
654.757	50
654.912	50
655.068	54
655.223	58
655.379	50
655.535	50
655.69	50
655.846	48
656.001	50
656.157	58
656.313	40
656.468	52
656.624	44
656.779	44
656.935	46
657.09	48
657.246	50
657.401	46
657.557	44
657.712	58
657.868	58
658.024	46
658.179	50
658.335	52
658.49	56
658.646	46
658.801	44
658.957	52
659.112	60
659.268	54
659.423	48
659.578	46
659.734	50
659.889	48
660.045	54
660.2	56
660.356	50
660.511	48
660.667	42
660.822	50
660.978	46
661.133	58
661.288	44
661.444	42
661.599	60
661.755	54
661.91	50
662.065	56
662.221	52
662.376	52
662.532	50
662.687	50
662.842	38
662.998	56
663.153	44
663.308	48
663.464	52
663.619	38
663.774	46
663.93	42
664.085	44
664.24	52
664.396	40
664.551	44
664.706	40
664.862	48
665.017	64
665.172	50
665.328	46
665.483	52
665.638	52
665.793	48.015
665.949	58.0813
666.104	50
666.259	42.1302
666.414	38.4588
666.57	50.1888
666.725	53.9386
666.88	48.3392
667.035	54.4403
667.191	45.4337
667.346	47.6291
667.501	46.7775
667.656	45.25
667.811	50.5134
667.967	54.6422
668.122	54.2825
668.277	49.861
668.432	53.2585
668.587	50.3854
668.743	48.9576
668.898	50.2074
669.053	48.1184
669.208	54.2403
669.363	51.0349
669.518	51.8995
669.673	50
669.829	46.2633
669.984	44.4266
670.139	50.505
670.294	50.9159
670.449	56.8495
670.604	53.0006
670.759	49.8881
670.914	51.9582
671.07	53.5342
671.225	52.4593
671.38	48.5346
671.535	49.4835
671.69	45.6352
671.845	51.5331
672	50.9248
672.155	60.234
672.31	43.4445
672.465	43.757
672.62	42.7715
672.775	48.3427
672.93	53.4263
673.085	56.9662
673.24	52.984
673.395	50.517
673.55	52.0163
673.705	49.2875
673.86	49.2063
674.015	56.4932
674.17	52.4996
674.325	47.0519
674.48	44.343
674.635	48
674.79	46.2835
674.945	52.7198
675.1	48.0683
675.255	54.7861
675.41	51.0618
675.565	49.5714
675.72	51.9244
675.875	52.4244
676.03	53.8389
676.182	54
676.338	56
676.493	46
676.649	46
676.804	52
676.96	46
677.116	58
677.271	60
677.427	48
677.582	64
677.738	60
677.893	58
678.049	60
678.205	42
678.36	52
678.516	52
678.671	50
678.827	50
678.982	56
679.138	54
679.293	60
679.449	66
679.604	58
679.76	58
679.915	56
680.071	58
680.227	54
680.382	54
680.537	52
680.693	56
680.849	50
681.004	60
681.159	48
681.315	52
681.47	48
681.626	54
681.781	52
681.937	56
682.092	48
682.248	58
682.403	50
682.559	50
682.714	48
682.869	50
683.025	42
683.18	52
683.336	54
683.491	54
683.646	70
683.802	56
683.957	60
684.113	46
684.268	58
684.423	58
684.579	50
684.734	56
684.89	44
685.045	50
685.2	60
685.356	46
685.511	56
685.666	44
685.822	46
685.977	56
686.132	38
686.288	50
686.443	50
686.598	58
686.754	56
686.909	44
687.064	56
687.22	44
687.375	54
687.53	42
687.685	60
687.841	46
687.996	54
688.151	42
688.307	46
688.462	54
688.617	44
688.772	50
688.928	50
689.083	40
689.238	50
689.393	50
689.548	50
689.704	46
689.859	50
690.014	48
690.169	46
690.325	50
690.48	52
690.635	50
690.79	48
690.945	60
691.1	52
691.256	44
691.411	50
691.566	50
691.721	46
691.876	42
692.031	50
692.187	50
692.342	54
692.497	46
692.652	52
692.807	48
692.962	36
693.117	42
693.272	50
693.428	54
693.583	38
693.738	50
693.893	36
694.048	48
694.203	46
694.358	52
694.513	48
694.668	50
694.823	54
694.978	58
695.133	48
695.289	38
695.444	40
695.599	46
695.754	44
695.909	54
696.064	48
696.219	50
696.374	52
696.529	38
696.684	48
696.839	44
696.994	48
697.149	46
697.304	52
697.459	48
697.614	54
697.769	50
697.924	50
698.078	48
698.233	54
698.388	46
698.543	58
698.698	34
698.853	44
699.008	44
699.163	38
699.318	48
699.473	48
699.628	50
699.783	44
699.938	38
700.093	38
700.247	46
700.402	38
700.557	44
700.712	42
700.867	34
701.022	44
701.177	48
701.331	48
701.486	38
701.641	36
701.796	44
701.951	38
702.106	36
702.26	42
702.415	44
702.57	46
702.725	52
702.88	44
703.034	34
703.189	36
703.344	36
703.499	44
703.654	42
703.808	42
703.963	38
704.118	40
704.273	42
704.427	48
704.582	38
704.737	38
704.892	44
705.046	38
705.201	38
705.356	32
705.51	42
705.665	34
705.82	44
705.975	30
706.129	36
706.284	36
706.439	36
706.593	42
706.748	34
706.903	34
707.057	34
707.212	32
707.367	38
707.521	34
707.676	42
707.831	30
707.985	40
708.14	38
708.294	41.9575
708.449	37.9944
708.604	39.9435
708.758	39.9
708.913	30.3077
709.067	36.2408
709.222	43.2678
709.377	27.9104
709.531	40.3033
709.686	40.5934
709.84	37.3324
709.995	33.5103
710.149	29.2284
710.304	33.3702
710.458	28.3996
710.613	31.8725
710.768	30.0102
710.922	34.5228
711.077	30.213
711.231	32.9085
711.386	33.199
711.54	39.1668
711.695	28.0063
711.849	31.3892
712.004	30.9537
712.158	39.111
712.313	31.2109
712.467	35.4464
712.622	32.3152
712.776	36.4279
712.93	36.587
713.085	32.9535
713.239	29.624
713.394	29.6274
713.548	33.6259
713.703	36.4781
713.857	35.1762
714.011	34.8809
714.166	26.8003
714.32	32.2922
714.475	37.1694
714.629	32.9034
714.784	32.1233
714.938	39.8571
715.092	36.1862
715.247	29.4755
715.401	31.5246
715.555	38.4774
715.71	32.867
715.864	35.9405
716.018	33.8468
716.173	36.602
716.327	30.1453
716.481	37.6442
716.636	36.5927
716.79	35.2221
716.944	33.67
717.099	35.9854
717.253	31.7025
717.407	30.338
717.562	30.7199
717.716	28.8456
717.87	29.1132
718.024	32.1095
718.179	35.1811
718.333	31.8079
718.487	30.4107
718.641	31.8188
718.777	32
718.932	30
719.087	34
719.242	36
719.397	24
719.552	24
719.706	32
719.861	36
720.016	36
720.171	34
720.326	34
720.481	40
720.636	34
720.791	44
720.946	24
721.101	24
721.256	36
721.411	24
721.565	26
721.72	24
721.875	30
722.03	28
722.185	28
722.34	38
722.495	24
722.65	34
722.804	26
722.959	34
723.114	32
723.269	28
723.424	22
723.579	34
723.733	28
723.888	32
724.043	30
724.198	38
724.353	32
724.508	34
724.662	34
724.817	32
724.972	32
725.127	34
725.281	30
725.436	40
725.591	36
725.746	28
725.901	36
726.055	28
726.21	36
726.365	26
726.519	24
726.674	36
726.829	30
726.984	30
727.138	28
727.293	26
727.448	28
727.603	32
727.757	28
727.912	26
728.067	26
728.221	28
728.376	26
728.531	28
728.685	26
728.84	28
728.995	30
729.149	28
729.304	32
729.459	30
729.613	32
729.768	22
729.923	30
730.077	32
730.232	18
730.386	26
730.541	20
730.696	26
730.85	32
731.005	22
731.159	30
731.314	34
731.469	28
731.623	30
731.778	28
731.932	30
732.087	34
732.241	28
732.396	34
732.551	36
732.705	32
732.86	30
733.014	22
733.169	34
733.323	28
733.478	28
733.632	30
733.787	22
733.941	28
734.096	18
734.25	28
734.405	30
734.559	30
734.714	20
734.868	20
735.023	24
735.177	26
735.332	32
735.486	24
735.64	24
735.795	24
735.949	26
736.104	22
736.258	30
736.413	26
736.567	38
736.721	30
736.876	32
737.03	28
737.185	28
737.339	24
737.493	38
737.648	26
737.802	30
737.957	28
738.111	26
738.265	24
738.42	28
738.574	28
738.728	34
738.883	30
739.037	38
739.191	32
739.346	32
739.5	20
739.654	20
739.809	24
739.963	32
740.117	34
740.271	38
740.426	20
740.58	28
740.734	22
740.889	26
741.043	32
741.197	26
741.351	20
741.506	24
741.66	26
741.814	28
741.968	24
742.123	24
742.277	30
742.431	24
742.585	30
742.739	34
742.894	22
743.048	26
743.202	28
743.356	26
743.51	24
743.665	28
743.819	20
743.973	32
744.127	22
744.281	28
744.435	26
744.59	26
744.744	32
744.898	30
745.052	34
745.206	30
745.36	30
745.514	24
745.668	36
745.823	36
745.977	30
746.131	34
746.285	24
746.439	30
746.593	24
746.747	16
746.901	34
747.055	26
747.209	30
747.363	14
747.517	22
747.671	24
747.825	28
747.979	24
748.133	30
748.287	26
748.441	26
748.595	20
748.749	30
748.903	24
749.057	24
749.211	28
749.365	26
749.519	30
749.673	26
749.827	28
749.981	26
750.135	24
750.289	34
750.443	26
750.597	34
750.751	26
750.905	28
751.059	30
751.213	30
751.367	22
751.52	28
751.674	18
751.828	20
751.982	20
752.136	28
752.29	28
752.444	28
752.598	22
752.751	24
752.905	22
753.059	26
753.213	22
753.367	28
753.521	32
753.674	22
753.828	26
753.982	24
754.136	22
754.29	20
754.444	20
754.597	22
754.751	22
754.905	24
755.059	22
755.212	16
755.366	16
755.52	26
755.674	26
755.827	30
755.981	26
756.135	26
756.289	16
756.442	24
756.596	26
756.75	20
756.903	24
757.057	24
757.211	26
757.365	26
757.518	28
757.672	26
757.826	30
757.979	26
758.133	18
758.287	26
758.44	24
758.594	32
758.747	32
758.901	24
759.055	28
759.208	26
759.362	24
759.516	28
759.669	20
759.823	20
759.976	20