File: TestFile/240 10%-1.txt
#Acq. time (s)=	1
#Accumulations=	1
#Range (nm)=	535...800
#Windows=	6
#Auto scanning=	Off
#Autofocus=	Off
#AutoExposure=	Off
#Spike filter=	Off
#Delay time (s)=	0
#Binning=	1
#Readout mode=	Signal
#DeNoise=	Off
#ICS correction=	Off
#Dark correction=	Off
#Inst. Process=	Off
#Detector temperature (°C)=	-60.16
#Instrument=	LabRAM HR Evol
#Detector=	Syncerity OE
#Objective=	x100_VIS
#Grating=	600 (500nm)
#ND Filter=	10%
#Laser=	532nm_Edge
#Hole=	300.003
#Range=	Visible
#AFM=	Off
#Laser. Pol.=	HWPL-VIS
#Raman. Pol.=	P-350/2300
#Laser Pol. (°)=	180
#Raman Pol. (°)=	130
#StageXY (mm)=	75x50
#StageZ=	Z motor
#X (µm)=	-27063.9
#Y (µm)=	-1972.1
#Z (µm)=	573
#Full time(s)=	40
#Project=	A
#Sample=	B
#Site=	C
#Title=	-30-3-0p1_75
#Remark=
#Date=	14.08.2020 14:36
#Acquired=	14.08.2020 14:36:36
535.014	50
535.224	38
535.434	36
535.644	42
535.855	44
536.065	48
536.275	46
536.485	38
536.695	48
536.906	52
537.116	54
537.326	48
537.536	56
537.746	54
537.956	60
538.166	44
538.377	56
538.587	52
538.797	52
539.007	52
539.217	42
539.427	42
539.637	42
539.847	36
540.057	40
540.267	44
540.477	40
540.687	36
540.897	42
541.107	44
541.318	42
541.528	38
541.738	48
541.948	54
542.158	44
542.368	60
542.578	54
542.788	78
542.998	98
543.208	160
543.417	142
543.627	76
543.837	138
544.047	338
544.257	138
544.467	70
544.677	54
544.887	66
545.097	64
545.307	76
545.517	68
545.727	62
545.937	56
546.146	52
546.356	54
546.566	60
546.776	48
546.986	54
547.196	48
547.406	50
547.615	44
547.825	52
548.035	46
548.245	44
548.455	48
548.664	48
548.874	50
549.084	58
549.294	58
549.504	56
549.713	64
549.923	50
550.133	46
550.343	54
550.552	54
550.762	44
550.972	56
551.181	42
551.391	44
551.601	44
551.811	46
552.02	38
552.23	40
552.44	36
552.649	38
552.859	42
553.069	40
553.278	44
553.488	44
553.697	46
553.907	46
554.117	50
554.326	46
554.536	54
554.745	46
554.955	48
555.165	36
555.374	42
555.584	44
555.793	48
556.003	44
556.212	44
556.422	44
556.631	36
556.841	40
557.051	44
557.26	42
557.47	38
557.679	44
557.888	44
558.098	44
558.307	40
558.517	38
558.726	34
558.936	42
559.145	36
559.355	30
559.564	42
559.773	48
559.983	40
560.192	38
560.402	36
560.611	38
560.82	38
561.03	40
561.239	24
561.449	38
561.658	36
561.867	42
562.077	30
562.286	36
562.495	38
562.705	40
562.914	26
563.123	26
563.332	36
563.542	30
563.751	28
563.96	30
564.17	34
564.379	28
564.588	26
564.797	28
565.007	34
565.216	38
565.425	42
565.634	28
565.843	32
566.053	28
566.262	28
566.471	28
566.68	36
566.889	32
567.098	34
567.307	36
567.517	34
567.726	28
567.935	36
568.144	34
568.353	42
568.562	40
568.771	22
568.98	34
569.189	34
569.398	36
569.608	34
569.817	34
570.026	42
570.235	42
570.444	36
570.653	38
570.862	30
571.071	32
571.28	44
571.489	34
571.698	30
571.907	32
572.116	34
572.325	22
572.533	32
572.742	28
572.951	30
573.16	30
573.369	24
573.578	32
573.787	30
573.996	36
574.205	30
574.414	38
574.622	26
574.831	36
575.04	36
575.249	22
575.458	22
575.667	38
575.875	34
576.084	26
576.293	30
576.502	40
576.711	36
576.919	38
577.128	30
577.337	22
577.546	38
577.754	24
577.963	30
578.172	24.1359
578.381	33.7532
578.589	31.859
578.798	33.5165
579.007	33.3684
579.215	26.1395
579.424	30.1517
579.633	30.4727
579.841	29.7736
580.05	27.1791
580.259	28.6959
580.467	29.2696
580.676	31.3345
580.884	31.0526
581.093	25.892
581.302	26.4719
581.51	21.6791
581.719	31.7065
581.927	31.0633
582.136	25.8182
582.344	26.7873
582.553	33.6001
582.762	28.1117
582.97	31.7015
583.179	33.9801
583.387	28.704
583.596	25.209
583.804	32.6512
584.013	28.8507
584.221	27.4756
584.43	33.6321
584.638	26.9698
584.846	35.3617
585.055	29.4356
585.263	28.1091
585.472	30.6108
585.68	26.2124
585.889	27.2436
586.097	30.6134
586.305	21.7796
586.514	29.5558
586.722	28.1723
586.93	32.3071
587.139	30.9165
587.347	30.2139
587.555	34.8592
587.764	27.9676
587.972	32.0022
588.18	34.7306
588.389	27.456
588.56	28
588.769	34
588.979	24
589.188	28
589.397	24
589.606	34
589.815	24
590.024	24
590.233	34
590.442	22
590.651	26
590.86	28
591.069	36
591.279	28
591.488	28
591.697	28
591.906	26
592.115	26
592.324	30
592.533	32
592.742	38
592.951	30
593.16	34
593.369	30
593.578	30
593.787	38
593.996	30
594.205	30
594.413	32
594.622	32
594.831	28
595.04	32
595.249	24
595.458	34
595.667	36
595.876	34
596.085	28
596.294	32
596.503	34
596.711	22
596.92	20
597.129	30
597.338	20
597.547	34
597.756	28
597.964	28
598.173	44
598.382	24
598.591	34
598.8	30
599.008	34
599.217	28
599.426	28
599.635	26
599.843	38
600.052	32
600.261	38
600.47	46
600.678	32
600.887	34
601.096	30
601.304	28
601.513	24
601.722	34
601.93	28
602.139	28
602.348	30
602.556	32
602.765	30
602.974	24
603.182	26
603.391	28
603.599	36
603.808	36
604.017	24
604.225	32
604.434	30
604.642	34
604.851	36
605.06	22
605.268	38
605.477	34
605.685	32
605.894	32
606.102	34
606.311	36
606.519	34
606.728	32
606.936	34
607.145	30
607.353	28
607.562	38
607.77	30
607.978	34
608.187	32
608.395	32
608.604	28
608.812	34
609.021	38
609.229	34
609.437	38
609.646	42
609.854	30
610.062	36
610.271	28
610.479	44
610.687	42
610.896	34
611.104	34
611.312	36
611.521	30
611.729	40
611.937	42
612.146	34
612.354	40
612.562	28
612.77	28
612.979	30
613.187	38
613.395	30
613.603	34
613.812	42
614.02	38
614.228	42
614.436	36
614.644	36
614.852	30
615.061	30
615.269	28
615.477	44
615.685	38
615.893	38
616.101	38
616.309	36
616.518	28
616.726	34
616.934	36
617.142	32
617.35	32
617.558	38
617.766	34
617.974	42
618.182	32
618.39	38
618.598	32
618.806	40
619.014	36
619.222	38
619.43	42
619.638	34
619.846	34
620.054	38
620.262	40
620.47	36
620.678	38
620.886	46
621.094	41.856
621.301	37.964
621.509	34.1686
621.717	49.3122
621.925	44.5192
622.133	38.0137
622.341	40.0355
622.549	37.695
622.757	40.944
622.964	39.6028
623.172	38.4242
623.38	40.1437
623.588	36.5916
623.796	38.0369
624.003	32.6413
624.211	40.2758
624.419	39.8295
624.627	38.1866
624.834	37.8892
625.042	37.8712
625.25	33.2769
625.458	36.6119
625.665	38.9243
625.873	38.1003
626.081	37.0099
626.289	39.2566
626.496	39.8171
626.704	42.4527
626.912	42.3372
627.119	39.6865
627.327	40.0375
627.534	40.6486
627.742	44.8702
627.95	43.3483
628.157	40.104
628.365	44.8557
628.573	44.9186
628.78	39.8745
628.988	42
629.195	38.8586
629.403	40.4951
629.61	43.8347
629.818	42.4432
630.025	38.2009
630.233	38.4858
630.44	48.5765
630.648	39.1305
630.855	45.23
631.063	47.6947
631.27	43.3274
631.461	44
631.669	38
631.878	42
632.086	46
632.294	50
632.503	44
632.711	60
632.919	44
633.128	46
633.336	58
633.544	54
633.753	46
633.961	48
634.169	48
634.377	48
634.586	58
634.794	56
635.002	52
635.21	46
635.418	52
635.627	52
635.835	40
636.043	46
636.251	42
636.459	52
636.668	48
636.876	46
637.084	46
637.292	48
637.5	52
637.708	70
637.916	52
638.125	48
638.333	52
638.541	46
638.749	54
638.957	40
639.165	54
639.373	56
639.581	58
639.789	62
639.997	62
640.205	58
640.413	56
640.621	58
640.829	56
641.037	56
641.245	66
641.453	72
641.661	54
641.869	58
642.077	62
642.285	50
642.493	76
642.701	66
642.909	66
643.117	56
643.325	64
643.533	68
643.741	72
643.949	62
644.156	64
644.364	62
644.572	66
644.78	72
644.988	64
645.196	70
645.404	78
645.611	74
645.819	70
646.027	76
646.235	90
646.443	78
646.65	68
646.858	82
647.066	70
647.274	82
647.482	92
647.689	80
647.897	76
648.105	86
648.312	86
648.52	88
648.728	92
648.936	98
649.143	100
649.351	86
649.559	96
649.766	90
649.974	88
650.182	92
650.389	100
650.597	94
650.804	104
651.012	106
651.22	100
651.427	86
651.635	98
651.842	98
652.05	100
652.258	114
652.465	102
652.673	106
652.88	114
653.088	112
653.295	124
653.503	128
653.71	104
653.918	98
654.125	106
654.333	102
654.54	100
654.748	108
654.955	110
655.163	118
655.37	118
655.577	108
655.785	112
655.992	118
656.2	110
656.407	106
656.614	116
656.822	108
657.029	126
657.236	108
657.444	120
657.651	120
657.858	124
658.066	124
658.273	118
658.48	96
658.688	124
658.895	128
659.102	112
659.31	116
659.517	118
659.724	124
659.931	112
660.138	114
660.346	112
660.553	116
660.76	114
660.967	122
661.174	118
661.382	120
661.589	126
661.796	114
662.003	112
662.21	98
662.417	112
662.625	110
662.832	102
663.039	104
663.246	116
663.453	98
663.66	104.061
663.867	119.869
664.074	109.862
664.281	114.613
664.488	100.549
664.695	108.552
664.902	101.85
665.109	103.618
665.316	98.453
665.523	95.4705
665.73	105.845
665.937	105.001
666.144	101.648
666.351	109.284
666.558	92.8434
666.765	98.4863
666.972	106.102
667.179	105.125
667.386	104.846
667.593	95.2365
667.8	91.476
668.007	90.3187
668.213	95.8558
668.42	98.9872
668.627	93.6979
668.834	96.8237
669.041	85.2331
669.248	100.184
669.455	90.0548
669.661	90.3479
669.868	96.3118
670.075	85.0327
670.282	89.2864
670.488	78.2584
670.695	84.5368
670.902	95.3137
671.109	86.2907
671.315	88.092
671.522	82.1879
671.729	83.3879
671.936	86.0463
672.142	89.2859
672.349	77.1591
672.556	80.9121
672.762	82.8977
672.969	83.9699
673.176	79.8256
673.382	78.5684
673.589	85.8615
673.796	88.1113
674.002	82.7077
674.177	80
674.385	88
674.592	86
674.8	82
675.007	78
675.215	76
675.422	86
675.63	80
675.837	66
676.045	78
676.252	78
676.46	76
676.667	78
676.875	88
677.082	66
677.289	82
677.497	84
677.704	74
677.912	76
678.119	70
678.326	68
678.534	76
678.741	74
678.948	70
679.156	78
679.363	84
679.57	72
679.778	62
679.985	74
680.192	60
680.4	70
680.607	68
680.814	66
681.022	64
681.229	70
681.436	74
681.643	66
681.851	62
682.058	64
682.265	64
682.472	70
682.679	60
682.887	58
683.094	66
683.301	60
683.508	52
683.715	72
683.922	68
684.13	64
684.337	70
684.544	70
684.751	58
684.958	64
685.165	60
685.372	58
685.579	56
685.786	54
685.994	60
686.201	54
686.408	48
686.615	58
686.822	48
687.029	62
687.236	52
687.443	56
687.65	56
687.857	70
688.064	58
688.271	52
688.478	56
688.685	62
688.892	64
689.099	64
689.306	58
689.513	56
689.719	52
689.926	56
690.133	60
690.34	54
690.547	50
690.754	58
690.961	58
691.168	54
691.375	48
691.581	52
691.788	52
691.995	54
692.202	58
692.409	62
692.615	48
692.822	56
693.029	46
693.236	52
693.443	52
693.649	58
693.856	54
694.063	56
694.269	50
694.476	48
694.683	58
694.89	46
695.096	62
695.303	50
695.51	48
695.716	54
695.923	52
696.13	50
696.336	52
696.543	58
696.75	52
696.956	44
697.163	52
697.369	54
697.576	42
697.782	46
697.989	54
698.196	52
698.402	50
698.609	50
698.815	48
699.022	52
699.228	48
699.435	50
699.641	54
699.848	54
700.054	56
700.261	46
700.467	50
700.674	48
700.88	42
701.086	38
701.293	40
701.499	58
701.706	50
701.912	44
702.118	56
702.325	42
702.531	46
702.738	54
702.944	42
703.15	46
703.357	40
703.563	38
703.769	34
703.976	48
704.182	52
704.388	44
704.594	54
704.801	52
705.007	40
705.213	40
705.419	40
705.626	44
705.832	46
706.038	30
706.244	41.9328
706.45	32.4524
706.657	49.6219
706.863	44.8652
707.069	50.9474
707.275	44.9324
707.481	37.1191
707.687	40.5109
707.893	42.3868
708.1	39.3334
708.306	35.5221
708.512	46.3097
708.718	52.3275
708.924	36.7483
709.13	53.1314
709.336	40.6321
709.542	39.6801
709.748	37.3085
709.954	40.5002
710.16	41.5535
710.366	44.1138
710.572	39.6436
710.778	35.0163
710.984	44.4194
711.19	42.9104
711.396	41.0485
711.602	44.2293
711.808	39.0896
712.014	34.88
712.22	45.8713
712.426	37.3334
712.632	36
712.838	35.0454
713.043	41.3225
713.249	33.4648
713.455	39.8197
713.661	38.9504
713.867	42.6565
714.073	41.7524
714.278	43.8055
714.484	35.1159
714.69	40.0369
714.896	43.6786
715.102	39.1791
715.307	41.7098
715.513	38.3067
715.719	30.8234
715.925	35.7805
716.13	31.4074
716.336	39.6821
716.498	48
716.704	32
716.911	30
717.118	38
717.324	34
717.531	36
717.738	48
717.944	48
718.151	40
718.357	36
718.564	38
718.771	36
718.977	36
719.184	36
719.39	38
719.597	34
719.804	44
720.01	42
720.217	44
720.423	38
720.63	36
720.836	34
721.043	42
721.249	38
721.456	28
721.662	36
721.869	32
722.075	38
722.282	44
722.488	38
722.694	36
722.901	26
723.107	34
723.314	38
723.52	32
723.726	34
723.933	36
724.139	30
724.346	42
724.552	34
724.758	40
724.965	32
725.171	38
725.377	38
725.584	44
725.79	38
725.996	40
726.203	38
726.409	38
726.615	36
726.821	34
727.028	34
727.234	34
727.44	40
727.646	36
727.853	34
728.059	36
728.265	34
728.471	30
728.677	36
728.884	26
729.09	28
729.296	36
729.502	30
729.708	38
729.914	42
730.12	30
730.327	34
730.533	36
730.739	26
730.945	36
731.151	28
731.357	34
731.563	32
731.769	28
731.975	34
732.181	36
732.387	28
732.593	32
732.799	30
733.005	28
733.211	36
733.417	28
733.623	30
733.829	34
734.035	28
734.241	32
734.447	36
734.653	36
734.859	34
735.065	24
735.271	38
735.477	32
735.682	30
735.888	30
736.094	36
736.3	40
736.506	38
736.712	30
736.918	40
737.123	42
737.329	34
737.535	36
737.741	32
737.947	36
738.152	24
738.358	32
738.564	32
738.77	36
738.975	26
739.181	36
739.387	30
739.592	36
739.798	30
740.004	28
740.21	30
740.415	36
740.621	32
740.827	32
741.032	28
741.238	42
741.443	32
741.649	32
741.855	30
742.06	40
742.266	34
742.471	20
742.677	40
742.883	34
743.088	28
743.294	30
743.499	36
743.705	24
743.91	38
744.116	40
744.321	32
744.527	36
744.732	32
744.938	36
745.143	34
745.348	34
745.554	26
745.759	24
745.965	32
746.17	26
746.376	38
746.581	30
746.786	30
746.992	36
747.197	26
747.402	34
747.608	38
747.813	34
748.018	18
748.224	38
748.429	22
748.634	35.9901
748.84	43.6434
749.045	31.9984
749.25	29.6269
749.455	29.8358
749.661	29.5853
749.866	29.7129
750.071	31.1513
750.276	31.131
750.481	24.3632
750.687	37.3739
750.892	26.6616
751.097	22.9846
751.302	30.314
751.507	23.1251
751.712	28.3602
751.918	24.5672
752.123	30.5965
752.328	27.9931
752.533	27.5454
752.738	31.0696
752.943	18.5224
753.148	31.0182
753.353	27.4983
753.558	28.2752
753.763	24.0415
753.968	27.1896
754.173	23.7358
754.378	28.8474
754.583	27.0953
754.788	33.5729
754.993	27.9941
755.198	32.1431
755.403	21.2177
755.608	24.5499
755.813	25.7546
756.018	28.7836
756.223	27.676
756.428	29.4814
756.633	27.1291
756.838	25.0936
757.042	32.4698
757.247	24.0839
757.452	29.9293
757.657	28.8875
757.862	26.2535
758.067	28.588
758.272	31.3192
758.476	28
758.681	28.756
758.886	28.5509
759.053	28
759.258	24
759.464	30
759.67	28
759.876	30
760.081	20
760.287	26
760.493	30
760.699	22
760.904	32
761.11	28
761.316	24
761.521	30
761.727	26
761.933	20
762.138	32
762.344	28
762.55	28
762.755	34
762.961	22
763.167	20
763.372	32
763.578	34
763.783	24
763.989	36
764.195	22
764.4	24
764.606	30
764.811	26
765.017	24
765.222	32
765.428	28
765.633	26
765.839	32
766.044	30
766.25	28
766.455	26
766.661	28
766.866	28
767.072	18
767.277	30
767.482	20
767.688	32
767.893	28
768.099	24
768.304	20
768.509	32
768.715	30
768.92	22
769.126	30
769.331	32
769.536	22
769.742	30
769.947	28
770.152	28
770.358	30
770.563	26
770.768	26
770.973	26
771.179	28
771.384	32
771.589	28
771.794	18
772	28
772.205	26
772.41	36
772.615	28
772.82	28
773.026	24
773.231	20
773.436	36
773.641	30
773.846	36
774.051	26
774.257	22
774.462	30
774.667	22
774.872	24
775.077	28
775.282	20
775.487	30
775.692	22
775.897	22
776.102	28
776.307	26
776.512	24
776.717	26
776.922	30
777.127	28
777.332	24
777.537	32
777.742	24
777.947	28
778.152	22
778.357	34
778.562	28
778.767	26
778.972	26
779.177	24
779.382	28
779.587	26
779.792	26
779.996	18
780.201	28
780.406	26
780.611	26
780.816	32
781.021	28
781.225	24
781.43	24
781.635	28
781.84	30
782.045	26
782.249	28
782.454	20
782.659	26
782.864	28
783.068	20
783.273	22
783.478	26
783.682	24
783.887	26
784.092	32
784.296	24
784.501	32
784.706	20
784.91	30
785.115	18
785.32	30
785.524	16
785.729	24
785.933	26
786.138	22
786.342	14
786.547	20
786.752	20
786.956	30
787.161	16
787.365	32
787.57	20
787.774	32
787.979	20
788.183	28
788.388	20
788.592	24
788.796	22
789.001	24
789.205	24
789.41	30
789.614	22
789.818	28
790.023	30
790.227	22
790.432	28
790.636	18
790.84	24
791.045	30
791.249	26
791.453	26
791.658	28
791.862	32
792.066	18
792.27	26
792.475	22
792.679	28
792.883	20
793.087	20
793.292	26
793.496	20
793.7	18
793.904	22
794.108	28
794.313	26
794.517	32
794.721	18
794.925	28
795.129	32
795.333	28
795.537	18
795.742	22
795.946	30
796.15	18
796.354	24
796.558	20
796.762	22
796.966	22
797.17	20
797.374	24
797.578	22
797.782	16
797.986	28
798.19	24
798.394	18
798.598	20
798.802	26
799.006	26
799.21	26
799.414	14
799.617	18
799.821	26
799.974	30