File: TestFile/240 50%-1.txt
#Acq. time (s)=	1
#Accumulations=	1
#Range (nm)=	580...760
#Windows=	4
#Auto scanning=	Off
#Autofocus=	Off
#AutoExposure=	Off
#Spike filter=	Off
#Delay time (s)=	0
#Binning=	1
#Readout mode=	Signal
#DeNoise=	Off
#ICS correction=	Off
#Dark correction=	Off
#Inst. Process=	Off
#Detector temperature (°C)=	-60.16
#Instrument=	LabRAM HR Evol
#Detector=	Syncerity OE
#Objective=	x100_VIS
#Grating=	600 (500nm)
#ND Filter=	50%
#Laser=	532nm_Edge
#Hole=	300.003
#Range=	Visible
#AFM=	Off
#Laser. Pol.=	HWPL-VIS
#Raman. Pol.=	P-350/2300
#Laser Pol. (°)=	180
#Raman Pol. (°)=	130
#StageXY (mm)=	75x50
#StageZ=	Z motor
#X (µm)=	-26830.5
#Y (µm)=	-2277.2
#Z (µm)=	-1341.5
#Full time(s)=	35
#Project=	A
#Sample=	B
#Site=	C
#Title=	-30-3-0p1_78
#Remark=
#Date=	14.08.2020 14:48
#Acquired=	14.08.2020 14:48:58
580.073	38
580.23	30
580.387	36
580.544	30
580.701	40
580.858	28
581.015	36
581.172	30
581.329	40
581.486	20
581.643	32
581.8	26
581.957	34
582.114	22
582.271	24
582.429	32
582.586	30
582.743	32
582.9	32
583.057	34
583.214	28
583.371	30
583.528	28
583.685	28
583.842	32
583.999	26
584.156	28
584.313	28
584.47	34
584.627	32
584.784	30
584.941	16
585.097	20
585.254	28
585.411	22
585.568	32
585.725	26
585.882	30
586.039	26
586.196	28
586.353	32
586.51	24
586.667	24
586.824	28
586.981	32
587.138	26
587.295	22
587.452	34
587.608	26
587.765	28
587.922	30
588.079	32
588.236	32
588.393	38
588.55	30
588.707	36
588.864	34
589.02	26
589.177	40
589.334	28
589.491	32
589.648	32
589.805	32
589.962	38
590.118	26
590.275	38
590.432	30
590.589	28
590.746	30
590.903	28
591.059	30
591.216	32
591.373	26
591.53	32
591.687	32
591.843	40
592	30
592.157	32
592.314	32
592.471	26
592.627	30
592.784	30
592.941	34
593.098	28
593.255	26
593.411	32
593.568	34
593.725	28
593.882	32
594.038	32
594.195	28
594.352	30
594.508	28
594.665	36
594.822	32
594.979	34
595.135	30
595.292	26
595.449	24
595.605	26
595.762	32
595.919	30
596.076	32
596.232	28
596.389	30
596.546	28
596.702	28
596.859	28
597.016	38
597.172	34
597.329	26
597.486	30
597.642	22
597.799	26
597.956	32
598.112	36
598.269	34
598.425	30
598.582	36
598.739	32
598.895	36
599.052	34
599.208	32
599.365	28
599.522	30
599.678	30
599.835	28
599.991	26
600.148	38
600.305	30
600.461	32
600.618	30
600.774	28
600.931	30
601.087	40
601.244	30
601.401	28
601.557	40
601.714	28
601.87	30
602.027	24
602.183	30
602.34	30
602.496	28
602.653	34
602.809	26
602.966	34
603.122	28
603.279	38
603.435	40
603.592	34
603.748	32
603.905	28
604.061	26
604.218	42
604.374	38
604.531	36
604.687	40
604.843	36
605	28
605.156	36
605.313	34
605.469	36
605.626	30
605.782	28
605.938	38
606.095	40
606.251	32
606.408	32
606.564	40
606.72	32
606.877	38
607.033	40
607.19	28
607.346	34
607.502	40
607.659	32
607.815	24
607.971	28
608.128	40
608.284	36
608.441	24
608.597	30
608.753	32
608.91	38
609.066	30
609.222	34
609.379	34
609.535	26
609.691	38
609.847	34
610.004	36
610.16	30
610.316	40
610.473	44
610.629	36
610.785	34
610.942	42
611.098	40
611.254	32
611.41	40
611.567	34
611.723	38
611.879	44
612.035	42
612.192	36
612.348	38
612.504	50
612.66	46
612.816	38
612.973	36
613.129	36
613.285	34
613.441	40
613.597	50
613.754	42
613.91	38
614.066	34
614.222	42
614.378	40
614.535	36
614.691	30
614.847	44
615.003	40
615.159	40
615.315	46
615.471	36
615.628	34
615.784	28
615.94	30
616.096	36
616.252	48
616.408	42
616.564	40
616.72	38
616.877	38
617.033	36
617.189	42
617.345	34
617.501	42
617.657	40
617.813	44
617.969	44
618.125	44
618.281	44
618.437	46
618.593	50
618.749	48
618.905	46
619.061	48
619.217	46
619.373	48
619.529	42
619.685	40
619.841	50
619.997	40
620.154	36
620.31	52
620.465	42
620.621	40
620.777	40
620.933	58
621.089	44
621.245	56
621.401	56
621.557	42
621.713	44
621.869	46
622.025	56
622.181	46
622.337	50
622.493	52
622.649	44
622.805	56
622.961	47.9366
623.117	53.966
623.272	53.8401
623.428	51.9455
623.584	53.3683
623.74	47.4468
623.896	55.7674
624.052	54.2956
624.208	51.6007
624.364	44.5616
624.519	47.0815
624.675	45.5433
624.831	48.7969
624.987	52.5638
625.143	56.9165
625.299	45.6877
625.455	55.2205
625.61	53.931
625.766	56.1671
625.922	54.6562
626.078	54.5264
626.234	53.9324
626.389	44.9212
626.545	51.1029
626.701	50.5517
626.857	53.6732
627.013	49.7316
627.168	56.4384
627.324	54.1732
627.48	56.1958
627.636	53.5398
627.791	53.9695
627.947	48.1455
628.103	50.2017
628.259	55.0734
628.414	52.563
628.57	56.3092
628.726	52.9943
628.882	54.2744
629.037	51.4544
629.193	55.3134
629.349	48.2637
629.504	54.8742
629.66	57.2857
629.816	56.7787
629.971	53.9794
630.127	53.6729
630.283	53.0014
630.438	50.867
630.594	50.6701
630.75	57.9704
630.905	50.1071
631.061	55.8485
631.217	59.6823
631.372	60.7702
631.528	61.5551
631.684	58.6798
631.839	57.4468
631.995	57.1885
632.15	58.7627
632.306	56.9154
632.462	61.299
632.617	54.0401
632.773	62.8471
632.928	60.4559
633.084	67.2251
633.24	50.3103
633.395	52.5517
633.549	72
633.706	56
633.862	60
634.018	62
634.174	68
634.33	56
634.487	56
634.643	58
634.799	70
634.955	58
635.111	50
635.268	54
635.424	64
635.58	68
635.736	58
635.892	62
636.049	64
636.205	60
636.361	62
636.517	64
636.673	62
636.829	60
636.985	60
637.142	58
637.298	62
637.454	56
637.61	66
637.766	54
637.922	58
638.078	62
638.234	68
638.391	58
638.547	62
638.703	66
638.859	80
639.015	58
639.171	52
639.327	66
639.483	68
639.639	72
639.795	52
639.951	70
640.107	66
640.263	70
640.419	62
640.576	64
640.732	64
640.888	68
641.044	62
641.2	66
641.356	68
641.512	62
641.668	66
641.824	72
641.98	66
642.136	64
642.292	64
642.448	74
642.604	62
642.76	66
642.916	54
643.072	54
643.228	72
643.384	64
643.54	64
643.695	74
643.851	72
644.007	66
644.163	56
644.319	56
644.475	60
644.631	64
644.787	70
644.943	64
645.099	54
645.255	72
645.411	70
645.567	58
645.722	74
645.878	76
646.034	68
646.19	64
646.346	56
646.502	64
646.658	64
646.814	58
646.969	70
647.125	62
647.281	62
647.437	68
647.593	62
647.749	64
647.905	70
648.06	64
648.216	68
648.372	62
648.528	64
648.684	70
648.839	60
648.995	58
649.151	68
649.307	64
649.463	64
649.618	68
649.774	62
649.93	52
650.086	70
650.241	58
650.397	60
650.553	70
650.709	58
650.865	62
651.02	72
651.176	54
651.332	62
651.487	62
651.643	62
651.799	66
651.955	64
652.11	56
652.266	66
652.422	64
652.577	72
652.733	66
652.889	68
653.044	74
653.2	64
653.356	62
653.511	58
653.667	64
653.823	66
653.978	70
654.134	72
654.29	68
654.445	68
654.601	70
654.757	62
654.912	68
655.068	56
655.223	54
655.379	56
655.535	62
655.69	68
655.846	60
656.001	62
656.157	64
656.313	62
656.468	64
656.624	58
656.779	68
656.935	72
657.09	62
657.246	58
657.401	66
657.557	68
657.712	56
657.868	60
658.024	62
658.179	58
658.335	66
658.49	68
658.646	64
658.801	76
658.957	72
659.112	64
659.268	58
659.423	66
659.578	62
659.734	64
659.889	60
660.045	66
660.2	52
660.356	64
660.511	56
660.667	64
660.822	62
660.978	76
661.133	60
661.288	64
661.444	62
661.599	72
661.755	62
661.91	62
662.065	56
662.221	64
662.376	72
662.532	66
662.687	64
662.842	64
662.998	68
663.153	62
663.308	64
663.464	58
663.619	72
663.774	52
663.93	62
664.085	66
664.24	64
664.396	54
664.551	72
664.706	60
664.862	64
665.017	66
665.172	62
665.328	70
665.483	76
665.638	62
665.793	59.9537
665.949	66.1307
666.104	75.5236
666.259	65.7228
666.414	63.8829
666.57	72.0219
666.725	70.1643
666.88	70.9511
667.035	57.1825
667.191	55.5355
667.346	62.2032
667.501	75.3853
667.656	65.5091
667.811	68.4145
667.967	63.0821
668.122	62.3404
668.277	60.5729
668.432	64.3708
668.587	59.6187
668.743	63.5687
668.898	63.0298
669.053	61.1066
669.208	65.325
669.363	71.1103
669.518	64.6938
669.673	71.6782
669.829	64.2325
669.984	68.3461
670.139	67.4766
670.294	64.9159
670.449	66.4052
670.604	76.3347
670.759	65.8881
670.914	71.4527
671.07	69.5835
671.225	69.4431
671.38	63.4139
671.535	68.6168
671.69	68.6474
671.845	66.6847
672	69.8566
672.155	66.9755
672.31	67.275
672.465	65.3527
672.62	74.4922
672.775	70.2207
672.93	66.3305
673.085	71.3809
673.24	69.576
673.395	64.806
673.55	65.4595
673.705	71.1288
673.86	66.4917
674.015	67.6601
674.17	67.7797
674.325	65.2931
674.48	62.1549
674.635	68.7052
674.79	60.6703
674.945	69.0284
675.1	62.9921
675.255	64.9642
675.41	63.3971
675.565	64.2224
675.72	68.8132
675.875	66.2647
676.03	75.5716
676.182	64
676.338	72
676.493	56
676.649	72
676.804	66
676.96	64
677.116	76
677.271	74
677.427	70
677.582	76
677.738	68
677.893	62
678.049	62
678.205	68
678.36	70
678.516	70
678.671	72
678.827	74
678.982	68
679.138	84
679.293	56
679.449	68
679.604	78
679.76	62
679.915	74
680.071	60
680.227	74
680.382	62
680.537	64
680.693	68
680.849	62
681.004	72
681.159	68
681.315	76
681.47	64
681.626	80
681.781	64
681.937	76
682.092	70
682.248	64
682.403	68
682.559	70
682.714	66
682.869	70
683.025	70
683.18	60
683.336	66
683.491	70
683.646	72
683.802	74
683.957	80
684.113	72
684.268	74
684.423	70
684.579	74
684.734	54
684.89	78
685.045	66
685.2	78
685.356	62
685.511	64
685.666	68
685.822	66
685.977	66
686.132	72
686.288	72
686.443	74
686.598	72
686.754	64
686.909	68
687.064	64
687.22	64
687.375	70
687.53	74
687.685	68
687.841	74
687.996	84
688.151	70
688.307	64
688.462	72
688.617	78
688.772	62
688.928	74
689.083	72
689.238	70
689.393	72
689.548	72
689.704	72
689.859	74
690.014	70
690.169	84
690.325	72
690.48	70
690.635	74
690.79	68
690.945	74
691.1	72
691.256	72
691.411	66
691.566	68
691.721	68
691.876	66
692.031	70
692.187	76
692.342	70
692.497	56
692.652	52
692.807	74
692.962	64
693.117	74
693.272	66
693.428	60
693.583	76
693.738	68
693.893	70
694.048	68
694.203	72
694.358	78
694.513	74
694.668	60
694.823	70
694.978	68
695.133	66
695.289	58
695.444	60
695.599	52
695.754	66
695.909	74
696.064	70
696.219	60
696.374	70
696.529	62
696.684	58
696.839	62
696.994	68
697.149	64
697.304	60
697.459	62
697.614	68
697.769	70
697.924	82
698.078	70
698.233	62
698.388	66
698.543	74
698.698	60
698.853	60
699.008	64
699.163	66
699.318	62
699.473	54
699.628	64
699.783	66
699.938	68
700.093	62
700.247	64
700.402	60
700.557	60
700.712	66
700.867	64
701.022	54
701.177	62
701.331	54
701.486	62
701.641	68
701.796	66
701.951	66
702.106	66
702.26	52
702.415	56
702.57	60
702.725	68
702.88	62
703.034	62
703.189	58
703.344	52
703.499	54
703.654	58
703.808	54
703.963	64
704.118	56
704.273	62
704.427	56
704.582	62
704.737	66
704.892	58
705.046	70
705.201	66
705.356	52
705.51	66
705.665	56
705.82	52
705.975	60
706.129	52
706.284	56
706.439	54
706.593	50
706.748	58
706.903	58
707.057	62
707.212	60
707.367	48
707.521	56
707.676	52
707.831	64
707.985	60
708.14	54
708.294	48.0101
708.449	50.1861
708.604	50.2593
708.758	52.2137
708.913	61.0385
709.067	52.0705
709.222	43.3086
709.377	50.802
709.531	55.4975
709.686	58.9696
709.84	53.1007
709.995	64.2532
710.149	59.7401
710.304	60.3964
710.458	59.3137
710.613	43.5851
710.768	59.2587
710.922	48.9972
711.077	53.1885
711.231	49.1527
711.386	53.4713
711.54	54.0105
711.695	53.9969
711.849	58.1282
712.004	50.7241
712.158	51.3139
712.313	47.5665
712.467	49.0942
712.622	48.0706
712.776	43.1252
712.93	43.1005
713.085	50.4842
713.239	52.3261
713.394	53.4022
713.548	43.2815
713.703	49.99
713.857	49.7952
714.011	54.0181
714.166	46.8621
714.32	50.6051
714.475	44.3877
714.629	48.2271
714.784	42.4507
714.938	49.6531
715.092	51.9195
715.247	48.876
715.401	50.3253
715.555	48.7429
715.71	49.6721
715.864	48.2369
716.018	47.4012
716.173	47.4321
716.327	51.2406
716.481	46.9524
716.636	51.2963
716.79	47.6023
716.944	50.8951
717.099	48.7834
717.253	55.9854
717.407	44.283
717.562	44.9289
717.716	48.4101
717.87	45.1659
718.024	48.2463
718.179	57.0997
718.333	45.5538
718.487	48.7429
718.641	52.746
718.777	46
718.932	44
719.087	50
719.242	48
719.397	36
719.552	48
719.706	44
719.861	42
720.016	50
720.171	44
720.326	52
720.481	48
720.636	50
720.791	50
720.946	48
721.101	48
721.256	54
721.411	38
721.565	48
721.72	46
721.875	44
722.03	40
722.185	46
722.34	44
722.495	44
722.65	50
722.804	46
722.959	42
723.114	36
723.269	44
723.424	50
723.579	48
723.733	40
723.888	46
724.043	44
724.198	38
724.353	44
724.508	46
724.662	34
724.817	46
724.972	36
725.127	46
725.281	46
725.436	46
725.591	42
725.746	40
725.901	38
726.055	40
726.21	40
726.365	52
726.519	38
726.674	42
726.829	42
726.984	44
727.138	40
727.293	44
727.448	42
727.603	42
727.757	38
727.912	34
728.067	40
728.221	38
728.376	38
728.531	32
728.685	38
728.84	46
728.995	42
729.149	42
729.304	42
729.459	50
729.613	36
729.768	36
729.923	28
730.077	30
730.232	36
730.386	42
730.541	44
730.696	42
730.85	40
731.005	30
731.159	40
731.314	40
731.469	42
731.623	42
731.778	30
731.932	34
732.087	34
732.241	40
732.396	44
732.551	36
732.705	48
732.86	30
733.014	40
733.169	40
733.323	34
733.478	32
733.632	44
733.787	30
733.941	36
734.096	38
734.25	32
734.405	28
734.559	30
734.714	46
734.868	30
735.023	42
735.177	42
735.332	30
735.486	42
735.64	36
735.795	36
735.949	32
736.104	38
736.258	34
736.413	32
736.567	32
736.721	46
736.876	40
737.03	32
737.185	38
737.339	40
737.493	44
737.648	42
737.802	36
737.957	38
738.111	32
738.265	34
738.42	40
738.574	36
738.728	28
738.883	40
739.037	40
739.191	34
739.346	34
739.5	44
739.654	34
739.809	32
739.963	34
740.117	38
740.271	32
740.426	28
740.58	26
740.734	36
740.889	38
741.043	26
741.197	40
741.351	36
741.506	32
741.66	44
741.814	38
741.968	26
742.123	34
742.277	34
742.431	34
742.585	32
742.739	40
742.894	34
743.048	34
743.202	34
743.356	40
743.51	32
743.665	42
743.819	40
743.973	26
744.127	42
744.281	36
744.435	34
744.59	38
744.744	36
744.898	38
745.052	36
745.206	32
745.36	28
745.514	34
745.668	40
745.823	30
745.977	36
746.131	42
746.285	42
746.439	38
746.593	32
746.747	36
746.901	36
747.055	26
747.209	34
747.363	26
747.517	30
747.671	34
747.825	32
747.979	22
748.133	24
748.287	28
748.441	32
748.595	26
748.749	32
748.903	38
749.057	24
749.211	34
749.365	34
749.519	40
749.673	40
749.827	34
749.981	26
750.135	30
750.289	30
750.443	40
750.597	38
750.751	26
750.905	28
751.059	32
751.213	44
751.367	22
751.52	34
751.674	38
751.828	34
751.982	22
752.136	26
752.29	40
752.444	28
752.598	30
752.751	24
752.905	30
753.059	30
753.213	34
753.367	28
753.521	28
753.674	36
753.828	36
753.982	32
754.136	34
754.29	30
754.444	30
754.597	32
754.751	26
754.905	24
755.059	32
755.212	34
755.366	36
755.52	28
755.674	32
755.827	32
755.981	34
756.135	34
756.289	28
756.442	28
756.596	30
756.75	28
756.903	32
757.057	38
757.211	28
757.365	32
757.518	34
757.672	26
757.826	30
757.979	32
758.133	32
758.287	26
758.44	24
758.594	32
758.747	20
758.901	36
759.055	26
759.208	26
759.362	36
759.516	34
759.669	32
759.823	20
759.976	32